Workbook
Name Causa: #REF!
Name CC: #REF!
Name Comp_Auxil: #REF!
Name COMPOSIÇÃO: #REF!
Name encarregado: #REF!
Name EQUIPAMENTO: #REF!
Name função: #REF!
Name FUNCIONARIO: #REF!
Name INSUMP: #REF!
Name LOCAIS: #REF!
Name MATERIAL: #REF!
Name MO: #REF!
Name MVP_05: #REF!
Name NUMER_COMPOSIÇÃO: #REF!
Name Panilha_Resumo: #REF!
Name REGISTRO: #REF!
Name SEMANA: #REF!
Name TUNEL_0: #REF!+#REF!
Name TURNO: #REF!
Name UP_15: #REF!

Sheet Report Consolidado Semanal
BS2: Terraplanagem (C+A) Média m³/d | BU2: PCTE 4/5 | BV2: PCTE 06 | BW2: PCTE 7/8
D4: =Y7 -> 46217 | G4: ACOMPANHAMENTO SEMANAL 15 a 21/06 | K4: ACOMPANHAMENTO SEMANAL 22 a 28/06 | O4: ACOMPANHAMENTO SEMANAL 29 a 05/07 | S4: ACOMPANHAMENTO SEMANAL 06 a 12/07 | W4: ACOMPANHAMENTO DIÁRIO | AA4: ACOMPANHAMENTO SEMANAL | AK4: META MENSAL JUNHO/26 (Cronograma Corrente) | AP4: ACUMULADO BASELINE | AT4: ESCOPO CONTRATUAL | AW4: MÉDIA DIÁRIA (un/dia) | BS4: Média PLANEJADA MÊS | BU4: =SUM(AM13:AM18)+SUM(AM33:AM38) -> 628891.72 | BV4: =SUM(Gráficos!#REF!+Quadros!#REF!) -> #REF! | BW4: =Gráficos!#REF!+Gráficos!H7 -> #REF!
G5: 46054 | K5: 46054 | O5: 46054 | S5: 46054 | W5: 46054 | AA5: 46054 | AK5: 46054 | AW5: 46054 | AX5: 46054 | AY5: 46054
D6: ATIVIDADE | E6: UN | G6: P | R | H6: QUANT. | I6: ADERÊN. | K6: P | R | L6: QUANT. | M6: ADERÊN. | O6: P | R | P6: QUANT. | Q6: ADERÊN. | S6: P | R | T6: QUANT. | U6: ADERÊN. | W6: PRODUÇÃO DO DIA | Y6: =TEXT(Y7,"dDD") -> ter | AA6: =TEXT(AA7,"dDD") -> seg | AB6: =TEXT(AB7,"dDD") -> ter | AC6: =TEXT(AC7,"dDD") -> qua | AD6: =TEXT(AD7,"dDD") -> qui | AE6: =TEXT(AE7,"dDD") -> sex | AF6: =TEXT(AF7,"dDD") -> sáb | AG6: =TEXT(AG7,"dDD") -> dom | AH6: TOTAL SEMANA | AI6: ADERÊN CIA | AK6: PLANEJADO MÊS | AL6: PLANEJADO ATÉ A DATA | AM6: REAL MÊS | AN6: ADERÊN CIA | AP6: REAL ACUMULADO | AQ6: PREVISTO ACUMUL. BL | AR6: ADERÊN CIA | AT6: QUANT. TOTAL | AU6: SALDO | AW6: MÉDIA PLANEJADA | AX6: MÉDIA REAL MÊS | AY6: MÉDIA NECESSÁRIA | BS6: Média PLANEJADA MÊS | BU6: =SUM(Quadros!J12:J12)+SUM(Quadros!J37:J42) -> 628892.11 | BV6: =SUM(Quadros!J25+Gráficos!I3) -> #VALUE! | BW6: =Gráficos!#REF!+Quadros!#REF! -> #REF!
Y7: 46217 | AA7: 46216 | AB7: =AA7+1 -> 46217 | AC7: =AB7+1 -> 46218 | AD7: =AC7+1 -> 46219 | AE7: =AD7+1 -> 46220 | AF7: =AE7+1 -> 46221 | AG7: =AF7+1 -> 46222
D9: Escavação 1ª e 2ª categoria | E9: m³ | G9: P | H9: 377729.91 | I9: =IFERROR((H10/H9),"-") -> 0.87665404 | K9: P | L9: 477872 | M9: =IFERROR((L10/L9),"-") -> 0.90767756 | O9: P | P9: 381250.71 | Q9: =IFERROR((P10/P9),"-") -> 0.93445367 | S9: P | T9: 386884.07 | U9: 0.88993553 | W9: P | X9: =X13+X17+X21+X25 -> 66753.042 | Y9: =IFERROR((X10/X9),"-") -> 0.90809629 | AA9: =AA13+AA17+AA21+AA25 -> 66753.042 | AB9: =AB13+AB17+AB21+AB25 -> 66753.042 | AC9: =AC13+AC17+AC21+AC25 -> 66753.042 | AD9: =AD13+AD17+AD21+AD25 -> 66683.042 | AE9: =AE13+AE17+AE21+AE25 -> 62913.042 | AF9: =AF13+AF17+AF21+AF25 -> 62413.042 | AG9: =AG13+AG17+AG21+AG25 -> 0 | AH9: =SUMIF($AA$7:$AG$7,"<="&$D$4,$AA9:$AG9) -> 133506.08 | AI9: =IFERROR((AH10/AH9),"-") -> 0.92258874 | AK9: =AK13+AK17+AK21+AK25 -> 1739662.6 | AL9: =AL13+AL17+AL21+AL25 -> 906340.84 | AM9: =AM13+AM17+AM21+AM25 -> 718852.56 | AN9: =IFERROR((AM9/AL9),"-") -> 0.79313712 | AP9: =AP13+AP17+AP21+AP25 -> 4570782.1 | AQ9: =AQ13+AQ17+AQ21+AQ25 -> 6396534.4 | AR9: =IFERROR((AP9/AQ9),"-") -> 0.71457165 | AT9: =AT13+AT17+AT21+AT25 -> 15273579 | AU9: =AU13+AU17+AU21+AU25 -> 4621763.3 | AW9: =AW13+AW17+AW21+AW25 -> 64431.948 | AX9: =AX13+AX17+AX21+AX25 -> 59904.38 | AY9: =IF((AK9-AM9)/(Quadros!$D$4-Quadros!$D$6)<0,"-",(AK9-AM9)/(Quadros!$D$4-Quadros!$D$6)) -> 68054.003
G10: R | H10: 331138.45 | K10: R | L10: 433753.69 | O10: R | P10: 356261.13 | S10: R | T10: 344301.88 | W10: R | X10: =X14+X18+X22+X26 -> 60618.19 | AA10: =AA14+AA18+AA22+AA26 -> 62553.02 | AB10: =AB14+AB18+AB22+AB26 -> 60618.19 | AC10: =AC14+AC18+AC22+AC26 -> 0 | AD10: =AD14+AD18+AD22+AD26 -> 0 | AE10: =AE14+AE18+AE22+AE26 -> 0 | AF10: =AF14+AF18+AF22+AF26 -> 0 | AG10: =AG14+AG18+AG22+AG26 -> 0 | AH10: =SUMIF($AA$7:$AG$7,"<="&$D$4,$AA10:$AG10) -> 123171.21
A13: Pacote 04 - Segmento 2.2B- Km 104+500 a Km 116+400 | D13: Pacote 04 - km 104+500 a 131+260 | E13: m³ | G13: P | H13: 28760 | I13: =IFERROR((H14/H13),"-") -> 1.2764256 | K13: P | L13: 25160 | M13: =IFERROR((L14/L13),"-") -> 2.3211447 | O13: P | P13: 14920 | Q13: =IFERROR((P14/P13),"-") -> 1.9825737 | S13: P | T13: 32120 | U13: 0.87048568 | W13: P | X13: =SUMIF($AA$7:$AG$7,"="&$D$4,$AA13:$AG13) -> 7920 | Y13: =IFERROR((X14/X13),"-") -> 0.46969697 | AA13: =SUMIFS('Report Pacote 0405'!P:P,'Report Pacote 0405'!$AV:$AV,$D$9,'Report Pacote 0405'!$AW:$AW,$A$13,'Report Pacote 0405'!$H:$H,$W13)+SUMIFS('Report Pacote 0405'!P:P,'Report Pacote 0405'!$AV:$AV,$D$9,'Report Pacote 0405'!$AW:$AW,$A$14,'Report Pacote 0405'!$H:$H,$W13) -> 7920 | AB13: =SUMIFS('Report Pacote 0405'!Q:Q,'Report Pacote 0405'!$AV:$AV,$D$9,'Report Pacote 0405'!$AW:$AW,$A$13,'Report Pacote 0405'!$H:$H,$W13)+SUMIFS('Report Pacote 0405'!Q:Q,'Report Pacote 0405'!$AV:$AV,$D$9,'Report Pacote 0405'!$AW:$AW,$A$14,'Report Pacote 0405'!$H:$H,$W13) -> 7920 | AC13: =SUMIFS('Report Pacote 0405'!R:R,'Report Pacote 0405'!$AV:$AV,$D$9,'Report Pacote 0405'!$AW:$AW,$A$13,'Report Pacote 0405'!$H:$H,$W13)+SUMIFS('Report Pacote 0405'!R:R,'Report Pacote 0405'!$AV:$AV,$D$9,'Report Pacote 0405'!$AW:$AW,$A$14,'Report Pacote 0405'!$H:$H,$W13) -> 7920 | AD13: =SUMIFS('Report Pacote 0405'!S:S,'Report Pacote 0405'!$AV:$AV,$D$9,'Report Pacote 0405'!$AW:$AW,$A$13,'Report Pacote 0405'!$H:$H,$W13)+SUMIFS('Report Pacote 0405'!S:S,'Report Pacote 0405'!$AV:$AV,$D$9,'Report Pacote 0405'!$AW:$AW,$A$14,'Report Pacote 0405'!$H:$H,$W13) -> 7850 | AE13: =SUMIFS('Report Pacote 0405'!T:T,'Report Pacote 0405'!$AV:$AV,$D$9,'Report Pacote 0405'!$AW:$AW,$A$13,'Report Pacote 0405'!$H:$H,$W13)+SUMIFS('Report Pacote 0405'!T:T,'Report Pacote 0405'!$AV:$AV,$D$9,'Report Pacote 0405'!$AW:$AW,$A$14,'Report Pacote 0405'!$H:$H,$W13) -> 6880 | AF13: =SUMIFS('Report Pacote 0405'!U:U,'Report Pacote 0405'!$AV:$AV,$D$9,'Report Pacote 0405'!$AW:$AW,$A$13,'Report Pacote 0405'!$H:$H,$W13)+SUMIFS('Report Pacote 0405'!U:U,'Report Pacote 0405'!$AV:$AV,$D$9,'Report Pacote 0405'!$AW:$AW,$A$14,'Report Pacote 0405'!$H:$H,$W13) -> 6880 | AG13: =SUMIFS('Report Pacote 0405'!V:V,'Report Pacote 0405'!$AV:$AV,$D$9,'Report Pacote 0405'!$AW:$AW,$A$13,'Report Pacote 0405'!$H:$H,$W13)+SUMIFS('Report Pacote 0405'!V:V,'Report Pacote 0405'!$AV:$AV,$D$9,'Report Pacote 0405'!$AW:$AW,$A$14,'Report Pacote 0405'!$H:$H,$W13) -> 0 | AH13: =SUMIF($AA$7:$AG$7,"<="&$D$4,$AA13:$AG13) -> 15840 | AI13: =IFERROR((AH14/AH13),"-") -> 0.44002525 | AK13: =SUMIFS('Report Pacote 0405'!AA:AA,'Report Pacote 0405'!$AV:$AV,$D$9,'Report Pacote 0405'!$AW:$AW,$A$13,'Report Pacote 0405'!$H:$H,$W13)+SUMIFS('Report Pacote 0405'!AA:AA,'Report Pacote 0405'!$AV:$AV,$D$9,'Report Pacote 0405'!$AW:$AW,$A$14,'Report Pacote 0405'!$H:$H,$W13) -> 254338.81 | AL13: =SUMIFS('Report Pacote 0405'!AB:AB,'Report Pacote 0405'!$AV:$AV,$D$9,'Report Pacote 0405'!$AW:$AW,$A$13,'Report Pacote 0405'!$H:$H,$W13)+SUMIFS('Report Pacote 0405'!AB:AB,'Report Pacote 0405'!$AV:$AV,$D$9,'Report Pacote 0405'!$AW:$AW,$A$14,'Report Pacote 0405'!$H:$H,$W13) -> 197189.92 | AM13: =SUMIFS('Report Pacote 0405'!AC:AC,'Report Pacote 0405'!$AV:$AV,$D$9,'Report Pacote 0405'!$AW:$AW,$A$13,'Report Pacote 0405'!$H:$H,$W13)+SUMIFS('Report Pacote 0405'!AC:AC,'Report Pacote 0405'!$AV:$AV,$D$9,'Report Pacote 0405'!$AW:$AW,$A$14,'Report Pacote 0405'!$H:$H,$W13) -> 55110 | AN13: =IFERROR((AM13/AL13),"-") -> 0.27947676 | AP13: =SUMIFS('Report Pacote 0405'!AK:AK,'Report Pacote 0405'!$AV:$AV,$D$9,'Report Pacote 0405'!$AW:$AW,$A$13,'Report Pacote 0405'!$H:$H,$W13)+SUMIFS('Report Pacote 0405'!AK:AK,'Report Pacote 0405'!$AV:$AV,$D$9,'Report Pacote 0405'!$AW:$AW,$A$14,'Report Pacote 0405'!$H:$H,$W13) -> 3043207.2 | AQ13: =SUMIFS('Report Pacote 0405'!AL:AL,'Report Pacote 0405'!$AV:$AV,$D$9,'Report Pacote 0405'!$AW:$AW,$A$13,'Report Pacote 0405'!$H:$H,$W13)+SUMIFS('Report Pacote 0405'!AL:AL,'Report Pacote 0405'!$AV:$AV,$D$9,'Report Pacote 0405'!$AW:$AW,$A$14,'Report Pacote 0405'!$H:$H,$W13) -> 3163942.7 | AR13: =IFERROR((AP13/AQ13),"-") -> 0.96184016 | AT13: =SUMIFS('Report Pacote 0405'!AO:AO,'Report Pacote 0405'!$AV:$AV,$D$9,'Report Pacote 0405'!$AW:$AW,$A$13,'Report Pacote 0405'!$H:$H,$W13)+SUMIFS('Report Pacote 0405'!AO:AO,'Report Pacote 0405'!$AV:$AV,$D$9,'Report Pacote 0405'!$AW:$AW,$A$14,'Report Pacote 0405'!$H:$H,$W13) -> 3405031.3 | AU13: =SUMIFS('Report Pacote 0405'!AP:AP,'Report Pacote 0405'!$AV:$AV,$D$9,'Report Pacote 0405'!$AW:$AW,$A$13,'Report Pacote 0405'!$H:$H,$W13)+SUMIFS('Report Pacote 0405'!AP:AP,'Report Pacote 0405'!$AV:$AV,$D$9,'Report Pacote 0405'!$AW:$AW,$A$14,'Report Pacote 0405'!$H:$H,$W13) -> 361824.16 | AW13: =AK13/Quadros!$D$4 -> 9419.9559 | AX13: =AM13/Quadros!$D$6 -> 4592.5 | AY13: =IF((AK13-AM13)/(Quadros!$D$4-Quadros!$D$6)<0,"-",(AK13-AM13)/(Quadros!$D$4-Quadros!$D$6)) -> 13281.921
A14: Pacote 04 - Segmento 2.3 - Km 116+517 a 131+241 | G14: R | H14: 36710 | K14: R | L14: 58400 | O14: R | P14: 29580 | S14: R | T14: 27960 | W14: R | X14: =SUMIF($AA$7:$AG$7,"="&$D$4,$AA14:$AG14) -> 3720 | AA14: =SUMIFS('Report Pacote 0405'!P:P,'Report Pacote 0405'!$AV:$AV,$D$9,'Report Pacote 0405'!$AW:$AW,$A$13,'Report Pacote 0405'!$H:$H,$W14)+SUMIFS('Report Pacote 0405'!P:P,'Report Pacote 0405'!$AV:$AV,$D$9,'Report Pacote 0405'!$AW:$AW,$A$14,'Report Pacote 0405'!$H:$H,$W14) -> 3250 | AB14: =SUMIFS('Report Pacote 0405'!Q:Q,'Report Pacote 0405'!$AV:$AV,$D$9,'Report Pacote 0405'!$AW:$AW,$A$13,'Report Pacote 0405'!$H:$H,$W14)+SUMIFS('Report Pacote 0405'!Q:Q,'Report Pacote 0405'!$AV:$AV,$D$9,'Report Pacote 0405'!$AW:$AW,$A$14,'Report Pacote 0405'!$H:$H,$W14) -> 3720 | AC14: =SUMIFS('Report Pacote 0405'!R:R,'Report Pacote 0405'!$AV:$AV,$D$9,'Report Pacote 0405'!$AW:$AW,$A$13,'Report Pacote 0405'!$H:$H,$W14)+SUMIFS('Report Pacote 0405'!R:R,'Report Pacote 0405'!$AV:$AV,$D$9,'Report Pacote 0405'!$AW:$AW,$A$14,'Report Pacote 0405'!$H:$H,$W14) -> 0 | AD14: =SUMIFS('Report Pacote 0405'!S:S,'Report Pacote 0405'!$AV:$AV,$D$9,'Report Pacote 0405'!$AW:$AW,$A$13,'Report Pacote 0405'!$H:$H,$W14)+SUMIFS('Report Pacote 0405'!S:S,'Report Pacote 0405'!$AV:$AV,$D$9,'Report Pacote 0405'!$AW:$AW,$A$14,'Report Pacote 0405'!$H:$H,$W14) -> 0 | AE14: =SUMIFS('Report Pacote 0405'!T:T,'Report Pacote 0405'!$AV:$AV,$D$9,'Report Pacote 0405'!$AW:$AW,$A$13,'Report Pacote 0405'!$H:$H,$W14)+SUMIFS('Report Pacote 0405'!T:T,'Report Pacote 0405'!$AV:$AV,$D$9,'Report Pacote 0405'!$AW:$AW,$A$14,'Report Pacote 0405'!$H:$H,$W14) -> 0 | AF14: =SUMIFS('Report Pacote 0405'!U:U,'Report Pacote 0405'!$AV:$AV,$D$9,'Report Pacote 0405'!$AW:$AW,$A$13,'Report Pacote 0405'!$H:$H,$W14)+SUMIFS('Report Pacote 0405'!U:U,'Report Pacote 0405'!$AV:$AV,$D$9,'Report Pacote 0405'!$AW:$AW,$A$14,'Report Pacote 0405'!$H:$H,$W14) -> 0 | AG14: =SUMIFS('Report Pacote 0405'!V:V,'Report Pacote 0405'!$AV:$AV,$D$9,'Report Pacote 0405'!$AW:$AW,$A$13,'Report Pacote 0405'!$H:$H,$W14)+SUMIFS('Report Pacote 0405'!V:V,'Report Pacote 0405'!$AV:$AV,$D$9,'Report Pacote 0405'!$AW:$AW,$A$14,'Report Pacote 0405'!$H:$H,$W14) -> 0 | AH14: =SUMIF($AA$7:$AG$7,"<="&$D$4,$AA14:$AG14) -> 6970
A17: Pacote 05 - Segmento 2.4 - Km 131+260 a Km 138+000 | D17: Pacote 05 - km 131+260 a 167+300 | E17: m³ | G17: P | H17: 146880 | I17: =IFERROR((H18/H17),"-") -> 0.75909586 | K17: P | L17: 230520 | M17: =IFERROR((L18/L17),"-") -> 0.8181763 | O17: P | P17: 154880 | Q17: =IFERROR((P18/P17),"-") -> 0.99347882 | S17: P | T17: 149000 | U17: 0.99872483 | W17: P | X17: =SUMIF($AA$7:$AG$7,"="&$D$4,$AA17:$AG17) -> 25960 | Y17: =IFERROR((X18/X17),"-") -> 1.0805085 | AA17: =SUMIFS('Report Pacote 0405'!P:P,'Report Pacote 0405'!$AV:$AV,$D$9,'Report Pacote 0405'!$AW:$AW,$A$17,'Report Pacote 0405'!$H:$H,$W17)+SUMIFS('Report Pacote 0405'!P:P,'Report Pacote 0405'!$AV:$AV,$D$9,'Report Pacote 0405'!$AW:$AW,$A$18,'Report Pacote 0405'!$H:$H,$W17)+SUMIFS('Report Pacote 0405'!P:P,'Report Pacote 0405'!$AV:$AV,$D$9,'Report Pacote 0405'!$AW:$AW,$A$19,'Report Pacote 0405'!$H:$H,$W17) -> 25960 | AB17: =SUMIFS('Report Pacote 0405'!Q:Q,'Report Pacote 0405'!$AV:$AV,$D$9,'Report Pacote 0405'!$AW:$AW,$A$17,'Report Pacote 0405'!$H:$H,$W17)+SUMIFS('Report Pacote 0405'!Q:Q,'Report Pacote 0405'!$AV:$AV,$D$9,'Report Pacote 0405'!$AW:$AW,$A$18,'Report Pacote 0405'!$H:$H,$W17)+SUMIFS('Report Pacote 0405'!Q:Q,'Report Pacote 0405'!$AV:$AV,$D$9,'Report Pacote 0405'!$AW:$AW,$A$19,'Report Pacote 0405'!$H:$H,$W17) -> 25960 | AC17: =SUMIFS('Report Pacote 0405'!R:R,'Report Pacote 0405'!$AV:$AV,$D$9,'Report Pacote 0405'!$AW:$AW,$A$17,'Report Pacote 0405'!$H:$H,$W17)+SUMIFS('Report Pacote 0405'!R:R,'Report Pacote 0405'!$AV:$AV,$D$9,'Report Pacote 0405'!$AW:$AW,$A$18,'Report Pacote 0405'!$H:$H,$W17)+SUMIFS('Report Pacote 0405'!R:R,'Report Pacote 0405'!$AV:$AV,$D$9,'Report Pacote 0405'!$AW:$AW,$A$19,'Report Pacote 0405'!$H:$H,$W17) -> 25960 | AD17: =SUMIFS('Report Pacote 0405'!S:S,'Report Pacote 0405'!$AV:$AV,$D$9,'Report Pacote 0405'!$AW:$AW,$A$17,'Report Pacote 0405'!$H:$H,$W17)+SUMIFS('Report Pacote 0405'!S:S,'Report Pacote 0405'!$AV:$AV,$D$9,'Report Pacote 0405'!$AW:$AW,$A$18,'Report Pacote 0405'!$H:$H,$W17)+SUMIFS('Report Pacote 0405'!S:S,'Report Pacote 0405'!$AV:$AV,$D$9,'Report Pacote 0405'!$AW:$AW,$A$19,'Report Pacote 0405'!$H:$H,$W17) -> 25960 | AE17: =SUMIFS('Report Pacote 0405'!T:T,'Report Pacote 0405'!$AV:$AV,$D$9,'Report Pacote 0405'!$AW:$AW,$A$17,'Report Pacote 0405'!$H:$H,$W17)+SUMIFS('Report Pacote 0405'!T:T,'Report Pacote 0405'!$AV:$AV,$D$9,'Report Pacote 0405'!$AW:$AW,$A$18,'Report Pacote 0405'!$H:$H,$W17)+SUMIFS('Report Pacote 0405'!T:T,'Report Pacote 0405'!$AV:$AV,$D$9,'Report Pacote 0405'!$AW:$AW,$A$19,'Report Pacote 0405'!$H:$H,$W17) -> 23160 | AF17: =SUMIFS('Report Pacote 0405'!U:U,'Report Pacote 0405'!$AV:$AV,$D$9,'Report Pacote 0405'!$AW:$AW,$A$17,'Report Pacote 0405'!$H:$H,$W17)+SUMIFS('Report Pacote 0405'!U:U,'Report Pacote 0405'!$AV:$AV,$D$9,'Report Pacote 0405'!$AW:$AW,$A$18,'Report Pacote 0405'!$H:$H,$W17)+SUMIFS('Report Pacote 0405'!U:U,'Report Pacote 0405'!$AV:$AV,$D$9,'Report Pacote 0405'!$AW:$AW,$A$19,'Report Pacote 0405'!$H:$H,$W17) -> 23160 | AG17: =SUMIFS('Report Pacote 0405'!V:V,'Report Pacote 0405'!$AV:$AV,$D$9,'Report Pacote 0405'!$AW:$AW,$A$17,'Report Pacote 0405'!$H:$H,$W17)+SUMIFS('Report Pacote 0405'!V:V,'Report Pacote 0405'!$AV:$AV,$D$9,'Report Pacote 0405'!$AW:$AW,$A$18,'Report Pacote 0405'!$H:$H,$W17)+SUMIFS('Report Pacote 0405'!V:V,'Report Pacote 0405'!$AV:$AV,$D$9,'Report Pacote 0405'!$AW:$AW,$A$19,'Report Pacote 0405'!$H:$H,$W17) -> 0 | AH17: =SUMIF($AA$7:$AG$7,"<="&$D$4,$AA17:$AG17) -> 51920 | AI17: =IFERROR((AH18/AH17),"-") -> 1.1155624 | AK17: =SUMIFS('Report Pacote 0405'!AA:AA,'Report Pacote 0405'!$AV:$AV,$D$9,'Report Pacote 0405'!$AW:$AW,$A$18,'Report Pacote 0405'!$H:$H,$W17)+SUMIFS('Report Pacote 0405'!AA:AA,'Report Pacote 0405'!$AV:$AV,$D$9,'Report Pacote 0405'!$AW:$AW,$A$17,'Report Pacote 0405'!$H:$H,$W17)+SUMIFS('Report Pacote 0405'!AA:AA,'Report Pacote 0405'!$AV:$AV,$D$9,'Report Pacote 0405'!$AW:$AW,$A$19,'Report Pacote 0405'!$H:$H,$W17) -> 691424.32 | AL17: =SUMIFS('Report Pacote 0405'!AB:AB,'Report Pacote 0405'!$AV:$AV,$D$9,'Report Pacote 0405'!$AW:$AW,$A$18,'Report Pacote 0405'!$H:$H,$W17)+SUMIFS('Report Pacote 0405'!AB:AB,'Report Pacote 0405'!$AV:$AV,$D$9,'Report Pacote 0405'!$AW:$AW,$A$17,'Report Pacote 0405'!$H:$H,$W17)+SUMIFS('Report Pacote 0405'!AB:AB,'Report Pacote 0405'!$AV:$AV,$D$9,'Report Pacote 0405'!$AW:$AW,$A$19,'Report Pacote 0405'!$H:$H,$W17) -> 337781.76 | AM17: =SUMIFS('Report Pacote 0405'!AC:AC,'Report Pacote 0405'!$AV:$AV,$D$9,'Report Pacote 0405'!$AW:$AW,$A$18,'Report Pacote 0405'!$H:$H,$W17)+SUMIFS('Report Pacote 0405'!AC:AC,'Report Pacote 0405'!$AV:$AV,$D$9,'Report Pacote 0405'!$AW:$AW,$A$17,'Report Pacote 0405'!$H:$H,$W17)+SUMIFS('Report Pacote 0405'!AC:AC,'Report Pacote 0405'!$AV:$AV,$D$9,'Report Pacote 0405'!$AW:$AW,$A$19,'Report Pacote 0405'!$H:$H,$W17) -> 311650 | AN17: =IFERROR((AM17/AL17),"-") -> 0.92263715 | AP17: =SUMIFS('Report Pacote 0405'!AL:AL,'Report Pacote 0405'!$AV:$AV,$D$9,'Report Pacote 0405'!$AW:$AW,$A$18,'Report Pacote 0405'!$H:$H,$W17)+SUMIFS('Report Pacote 0405'!AL:AL,'Report Pacote 0405'!$AV:$AV,$D$9,'Report Pacote 0405'!$AW:$AW,$A$17,'Report Pacote 0405'!$H:$H,$W17)+SUMIFS('Report Pacote 0405'!AJ:AJ,'Report Pacote 0405'!$AV:$AV,$D$9,'Report Pacote 0405'!$AW:$AW,$A$19,'Report Pacote 0405'!$H:$H,$W17) -> 1463075.2 | AQ17: =SUMIFS('Report Pacote 0405'!AL:AL,'Report Pacote 0405'!$AV:$AV,$D$9,'Report Pacote 0405'!$AW:$AW,$A$13,'Report Pacote 0405'!$H:$H,$W17)+SUMIFS('Report Pacote 0405'!AL:AL,'Report Pacote 0405'!$AV:$AV,$D$9,'Report Pacote 0405'!$AW:$AW,$A$14,'Report Pacote 0405'!$H:$H,$W17) -> 3163942.7 | AR17: =IFERROR((AP17/AQ17),"-") -> 0.46242154 | AT17: =SUMIFS('Report Pacote 0405'!AO:AO,'Report Pacote 0405'!$AV:$AV,$D$9,'Report Pacote 0405'!$AW:$AW,$A$18,'Report Pacote 0405'!$H:$H,$W17)+SUMIFS('Report Pacote 0405'!AO:AO,'Report Pacote 0405'!$AV:$AV,$D$9,'Report Pacote 0405'!$AW:$AW,$A$17,'Report Pacote 0405'!$H:$H,$W17)+SUMIFS('Report Pacote 0405'!AN:AN,'Report Pacote 0405'!$AV:$AV,$D$9,'Report Pacote 0405'!$AW:$AW,$A$19,'Report Pacote 0405'!$H:$H,$W17) -> 2745772.9 | AU17: =SUMIFS('Report Pacote 0405'!AP:AP,'Report Pacote 0405'!$AV:$AV,$D$9,'Report Pacote 0405'!$AW:$AW,$A$18,'Report Pacote 0405'!$H:$H,$W17)+SUMIFS('Report Pacote 0405'!AP:AP,'Report Pacote 0405'!$AV:$AV,$D$9,'Report Pacote 0405'!$AW:$AW,$A$17,'Report Pacote 0405'!$H:$H,$W17)+SUMIFS('Report Pacote 0405'!AO:AO,'Report Pacote 0405'!$AV:$AV,$D$9,'Report Pacote 0405'!$AW:$AW,$A$19,'Report Pacote 0405'!$H:$H,$W17) -> 2422679.4 | AW17: =AK17/Quadros!$D$4 -> 25608.308 | AX17: =AM17/Quadros!$D$6 -> 25970.833 | AY17: =IF((AK17-AM17)/(Quadros!$D$4-Quadros!$D$6)<0,"-",(AK17-AM17)/(Quadros!$D$4-Quadros!$D$6)) -> 25318.288
A18: Pacote 05 - Segmento 2.5 - 138+160 a 153+420 | G18: R | H18: 111496 | K18: R | L18: 188606 | O18: R | P18: 153870 | S18: R | T18: 148810 | W18: R | X18: =SUMIF($AA$7:$AG$7,"="&$D$4,$AA18:$AG18) -> 28050 | AA18: =SUMIFS('Report Pacote 0405'!P:P,'Report Pacote 0405'!$AV:$AV,$D$9,'Report Pacote 0405'!$AW:$AW,$A$17,'Report Pacote 0405'!$H:$H,$W18)+SUMIFS('Report Pacote 0405'!P:P,'Report Pacote 0405'!$AV:$AV,$D$9,'Report Pacote 0405'!$AW:$AW,$A$18,'Report Pacote 0405'!$H:$H,$W18)+SUMIFS('Report Pacote 0405'!P:P,'Report Pacote 0405'!$AV:$AV,$D$9,'Report Pacote 0405'!$AW:$AW,$A$19,'Report Pacote 0405'!$H:$H,$W18) -> 29870 | AB18: =SUMIFS('Report Pacote 0405'!Q:Q,'Report Pacote 0405'!$AV:$AV,$D$9,'Report Pacote 0405'!$AW:$AW,$A$17,'Report Pacote 0405'!$H:$H,$W18)+SUMIFS('Report Pacote 0405'!Q:Q,'Report Pacote 0405'!$AV:$AV,$D$9,'Report Pacote 0405'!$AW:$AW,$A$18,'Report Pacote 0405'!$H:$H,$W18)+SUMIFS('Report Pacote 0405'!Q:Q,'Report Pacote 0405'!$AV:$AV,$D$9,'Report Pacote 0405'!$AW:$AW,$A$19,'Report Pacote 0405'!$H:$H,$W18) -> 28050 | AC18: =SUMIFS('Report Pacote 0405'!R:R,'Report Pacote 0405'!$AV:$AV,$D$9,'Report Pacote 0405'!$AW:$AW,$A$17,'Report Pacote 0405'!$H:$H,$W18)+SUMIFS('Report Pacote 0405'!R:R,'Report Pacote 0405'!$AV:$AV,$D$9,'Report Pacote 0405'!$AW:$AW,$A$18,'Report Pacote 0405'!$H:$H,$W18)+SUMIFS('Report Pacote 0405'!R:R,'Report Pacote 0405'!$AV:$AV,$D$9,'Report Pacote 0405'!$AW:$AW,$A$19,'Report Pacote 0405'!$H:$H,$W18) -> 0 | AD18: =SUMIFS('Report Pacote 0405'!S:S,'Report Pacote 0405'!$AV:$AV,$D$9,'Report Pacote 0405'!$AW:$AW,$A$17,'Report Pacote 0405'!$H:$H,$W18)+SUMIFS('Report Pacote 0405'!S:S,'Report Pacote 0405'!$AV:$AV,$D$9,'Report Pacote 0405'!$AW:$AW,$A$18,'Report Pacote 0405'!$H:$H,$W18)+SUMIFS('Report Pacote 0405'!S:S,'Report Pacote 0405'!$AV:$AV,$D$9,'Report Pacote 0405'!$AW:$AW,$A$19,'Report Pacote 0405'!$H:$H,$W18) -> 0 | AE18: =SUMIFS('Report Pacote 0405'!T:T,'Report Pacote 0405'!$AV:$AV,$D$9,'Report Pacote 0405'!$AW:$AW,$A$17,'Report Pacote 0405'!$H:$H,$W18)+SUMIFS('Report Pacote 0405'!T:T,'Report Pacote 0405'!$AV:$AV,$D$9,'Report Pacote 0405'!$AW:$AW,$A$18,'Report Pacote 0405'!$H:$H,$W18)+SUMIFS('Report Pacote 0405'!T:T,'Report Pacote 0405'!$AV:$AV,$D$9,'Report Pacote 0405'!$AW:$AW,$A$19,'Report Pacote 0405'!$H:$H,$W18) -> 0 | AF18: =SUMIFS('Report Pacote 0405'!U:U,'Report Pacote 0405'!$AV:$AV,$D$9,'Report Pacote 0405'!$AW:$AW,$A$17,'Report Pacote 0405'!$H:$H,$W18)+SUMIFS('Report Pacote 0405'!U:U,'Report Pacote 0405'!$AV:$AV,$D$9,'Report Pacote 0405'!$AW:$AW,$A$18,'Report Pacote 0405'!$H:$H,$W18)+SUMIFS('Report Pacote 0405'!U:U,'Report Pacote 0405'!$AV:$AV,$D$9,'Report Pacote 0405'!$AW:$AW,$A$19,'Report Pacote 0405'!$H:$H,$W18) -> 0 | AG18: =SUMIFS('Report Pacote 0405'!V:V,'Report Pacote 0405'!$AV:$AV,$D$9,'Report Pacote 0405'!$AW:$AW,$A$17,'Report Pacote 0405'!$H:$H,$W18)+SUMIFS('Report Pacote 0405'!V:V,'Report Pacote 0405'!$AV:$AV,$D$9,'Report Pacote 0405'!$AW:$AW,$A$18,'Report Pacote 0405'!$H:$H,$W18)+SUMIFS('Report Pacote 0405'!V:V,'Report Pacote 0405'!$AV:$AV,$D$9,'Report Pacote 0405'!$AW:$AW,$A$19,'Report Pacote 0405'!$H:$H,$W18) -> 0 | AH18: =SUMIF($AA$7:$AG$7,"<="&$D$4,$AA18:$AG18) -> 57920
A19: Pacote 05 - Segmento 3.1 - 153+000 a 167+400
D21: Pacote 06 - km 167+300 0 a 225+000 | E21: m³ | G21: P | H21: 154200 | I21: =IFERROR((H22/H21),"-") -> 0.78111219 | K21: P | L21: 160200 | M21: =IFERROR((L22/L21),"-") -> 0.78200687 | O21: P | P21: 145500 | Q21: =IFERROR((P22/P21),"-") -> 0.79949485 | S21: P | T21: 165700 | U21: 0.69180447 | W21: P | X21: =SUMIF($AA$7:$AG$7,"="&$D$4,$AA21:$AG21) -> 27200 | Y21: =IFERROR((X22/X21),"-") -> 0.74713235 | AA21: =SUMIFS('Report Pacote 06'!AG:AG,'Report Pacote 06'!$CH:$CH,$D$9,'Report Pacote 06'!$G:$G,'Report Consolidado Semanal'!$W21) -> 27200 | AB21: =SUMIFS('Report Pacote 06'!AH:AH,'Report Pacote 06'!$CH:$CH,$D$9,'Report Pacote 06'!$G:$G,'Report Consolidado Semanal'!$W21) -> 27200 | AC21: =SUMIFS('Report Pacote 06'!AI:AI,'Report Pacote 06'!$CH:$CH,$D$9,'Report Pacote 06'!$G:$G,'Report Consolidado Semanal'!$W21) -> 27200 | AD21: =SUMIFS('Report Pacote 06'!AJ:AJ,'Report Pacote 06'!$CH:$CH,$D$9,'Report Pacote 06'!$G:$G,'Report Consolidado Semanal'!$W21) -> 27200 | AE21: =SUMIFS('Report Pacote 06'!AK:AK,'Report Pacote 06'!$CH:$CH,$D$9,'Report Pacote 06'!$G:$G,'Report Consolidado Semanal'!$W21) -> 27200 | AF21: =SUMIFS('Report Pacote 06'!AL:AL,'Report Pacote 06'!$CH:$CH,$D$9,'Report Pacote 06'!$G:$G,'Report Consolidado Semanal'!$W21) -> 26700 | AG21: =SUMIFS('Report Pacote 06'!AM:AM,'Report Pacote 06'!$CH:$CH,$D$9,'Report Pacote 06'!$G:$G,'Report Consolidado Semanal'!$W21) -> 0 | AH21: =SUMIF($AA$7:$AG$7,"<="&$D$4,$AA21:$AG21) -> 54400 | AI21: =IFERROR((AH22/AH21),"-") -> 0.75565257 | AK21: =SUMIFS('Report Pacote 06'!BN:BN,'Report Pacote 06'!$CH:$CH,$D$9,'Report Pacote 06'!$G:$G,'Report Consolidado Semanal'!$W21) -> 571518.65 | AL21: =SUMIFS('Report Pacote 06'!BO:BO,'Report Pacote 06'!$CH:$CH,$D$9,'Report Pacote 06'!$G:$G,'Report Consolidado Semanal'!$W21) -> 254008.29 | AM21: =SUMIFS('Report Pacote 06'!BP:BP,'Report Pacote 06'!$CH:$CH,$D$9,'Report Pacote 06'!$G:$G,'Report Consolidado Semanal'!$W21) -> 226880 | AN21: =IFERROR((AM21/AL21),"-") -> 0.8931992 | AP21: =SUMIFS('Report Pacote 06'!BU:BU,'Report Pacote 06'!$CH:$CH,'Report Consolidado Semanal'!$D$49,'Report Pacote 06'!$G:$G,'Report Consolidado Semanal'!$W21) -> 57822.38 | AQ21: =SUMIFS('Report Pacote 06'!BX:BX,'Report Pacote 06'!$CH:$CH,'Report Consolidado Semanal'!$D$49,'Report Pacote 06'!$G:$G,'Report Consolidado Semanal'!$W21) -> 61971.608 | AR21: =IFERROR((AP21/AQ21),"-") -> 0.93304631 | AT21: =SUMIFS('Report Pacote 06'!CA:CA,'Report Pacote 06'!$CH:$CH,$D$9,'Report Pacote 06'!$G:$G,'Report Consolidado Semanal'!$W21) -> 6620711 | AU21: =SUMIFS('Report Pacote 06'!CB:CB,'Report Pacote 06'!$CH:$CH,$D$9,'Report Pacote 06'!$G:$G,'Report Consolidado Semanal'!$W21) -> 1473376.6 | AW21: =AK21/Quadros!$D$4 -> 21167.357 | AX21: =AM21/Quadros!$D$6 -> 18906.667 | AY21: =IF((AK21-AM21)/(Quadros!$D$4-Quadros!$D$6)<0,"-",(AK21-AM21)/(Quadros!$D$4-Quadros!$D$6)) -> 22975.91
G22: R | H22: 120447.5 | K22: R | L22: 125277.5 | O22: R | P22: 116326.5 | S22: R | T22: 114632 | W22: R | X22: =SUMIF($AA$7:$AG$7,"="&$D$4,$AA22:$AG22) -> 20322 | AA22: =SUMIFS('Report Pacote 06'!AG:AG,'Report Pacote 06'!$CH:$CH,$D$9,'Report Pacote 06'!$G:$G,'Report Consolidado Semanal'!$W22) -> 20785.5 | AB22: =SUMIFS('Report Pacote 06'!AH:AH,'Report Pacote 06'!$CH:$CH,$D$9,'Report Pacote 06'!$G:$G,'Report Consolidado Semanal'!$W22) -> 20322 | AC22: =SUMIFS('Report Pacote 06'!AI:AI,'Report Pacote 06'!$CH:$CH,$D$9,'Report Pacote 06'!$G:$G,'Report Consolidado Semanal'!$W22) -> 0 | AD22: =SUMIFS('Report Pacote 06'!AJ:AJ,'Report Pacote 06'!$CH:$CH,$D$9,'Report Pacote 06'!$G:$G,'Report Consolidado Semanal'!$W22) -> 0 | AE22: =SUMIFS('Report Pacote 06'!AK:AK,'Report Pacote 06'!$CH:$CH,$D$9,'Report Pacote 06'!$G:$G,'Report Consolidado Semanal'!$W22) -> 0 | AF22: =SUMIFS('Report Pacote 06'!AL:AL,'Report Pacote 06'!$CH:$CH,$D$9,'Report Pacote 06'!$G:$G,'Report Consolidado Semanal'!$W22) -> 0 | AG22: =SUMIFS('Report Pacote 06'!AM:AM,'Report Pacote 06'!$CH:$CH,$D$9,'Report Pacote 06'!$G:$G,'Report Consolidado Semanal'!$W22) -> 0 | AH22: =SUMIF($AA$7:$AG$7,"<="&$D$4,$AA22:$AG22) -> 41107.5
A25: Corte | D25: Pacote 07/08 - km 227+200 a 292+260 | E25: m³ | G25: P | H25: 47889.906 | I25: =IFERROR((H26/H25),"-") -> 1.3047624 | K25: P | L25: 61992 | M25: =IFERROR((L26/L25),"-") -> 0.99158262 | O25: P | P25: 65950.713 | Q25: =IFERROR((P26/P25),"-") -> 0.85646731 | S25: P | T25: 40064.071 | U25: 1.320382 | W25: P | X25: =SUMIF($AA$7:$AG$7,"="&$D$4,$AA25:$AG25) -> 5673.0421 | Y25: =IFERROR((X26/X25),"-") -> 1.5029309 | AA25: =SUMIFS('Report Pacote 07-08'!AL:AL,'Report Pacote 07-08'!$CB:$CB,$A25,'Report Pacote 07-08'!$J:$J,$W25) -> 5673.0421 | AB25: =SUMIFS('Report Pacote 07-08'!AM:AM,'Report Pacote 07-08'!$CB:$CB,$A25,'Report Pacote 07-08'!$J:$J,$W25) -> 5673.0421 | AC25: =SUMIFS('Report Pacote 07-08'!AN:AN,'Report Pacote 07-08'!$CB:$CB,$A25,'Report Pacote 07-08'!$J:$J,$W25) -> 5673.0421 | AD25: =SUMIFS('Report Pacote 07-08'!AO:AO,'Report Pacote 07-08'!$CB:$CB,$A25,'Report Pacote 07-08'!$J:$J,$W25) -> 5673.0421 | AE25: =SUMIFS('Report Pacote 07-08'!AP:AP,'Report Pacote 07-08'!$CB:$CB,$A25,'Report Pacote 07-08'!$J:$J,$W25) -> 5673.0421 | AF25: =SUMIFS('Report Pacote 07-08'!AQ:AQ,'Report Pacote 07-08'!$CB:$CB,$A25,'Report Pacote 07-08'!$J:$J,$W25) -> 5673.0421 | AG25: =SUMIFS('Report Pacote 07-08'!AR:AR,'Report Pacote 07-08'!$CB:$CB,$A25,'Report Pacote 07-08'!$J:$J,$W25) -> 0 | AH25: =SUMIF($AA$7:$AG$7,"<="&$D$4,$AA25:$AG25) -> 11346.084 | AI25: =IFERROR((AH26/AH25),"-") -> 1.5136244 | AK25: =SUMIFS('Report Pacote 07-08'!BM:BM,'Report Pacote 07-08'!$CB:$CB,$A25,'Report Pacote 07-08'!$J:$J,$W25) -> 222380.83 | AL25: =SUMIFS('Report Pacote 07-08'!BN:BN,'Report Pacote 07-08'!$CB:$CB,$A25,'Report Pacote 07-08'!$J:$J,$W25) -> 117360.87 | AM25: =SUMIFS('Report Pacote 07-08'!BO:BO,'Report Pacote 07-08'!$CB:$CB,$A25,'Report Pacote 07-08'!$J:$J,$W25) -> 125212.56 | AN25: =IFERROR((AM25/AL25),"-") -> 1.0669021 | AP25: =SUMIFS('Report Pacote 07-08'!AD:AD,'Report Pacote 07-08'!$CB:$CB,$A25,'Report Pacote 07-08'!$J:$J,$W25) -> 6677.3452 | AQ25: =SUMIFS('Report Pacote 07-08'!AI:AI,'Report Pacote 07-08'!$CB:$CB,$A25,'Report Pacote 07-08'!$J:$J,$W25) -> 6677.3452 | AR25: =IFERROR((AP25/AQ25),"-") -> 1 | AT25: =SUMIFS('Report Pacote 07-08'!BV:BV,'Report Pacote 07-08'!$CB:$CB,$A25,'Report Pacote 07-08'!$J:$J,$W25) -> 2502064 | AU25: =SUMIFS('Report Pacote 07-08'!BW:BW,'Report Pacote 07-08'!$CB:$CB,$A25,'Report Pacote 07-08'!$J:$J,$W25) -> 363883.14 | AW25: =AK25/Quadros!$D$4 -> 8236.327 | AX25: =AM25/Quadros!$D$6 -> 10434.38 | AY25: =IF((AK25-AM25)/(Quadros!$D$4-Quadros!$D$6)<0,"-",(AK25-AM25)/(Quadros!$D$4-Quadros!$D$6)) -> 6477.8846
A26: Corte | G26: R | H26: 62484.95 | K26: R | L26: 61470.19 | O26: R | P26: 56484.63 | S26: R | T26: 52899.88 | W26: R | X26: =SUMIF($AA$7:$AG$7,"="&$D$4,$AA26:$AG26) -> 8526.19 | AA26: =SUMIFS('Report Pacote 07-08'!AL:AL,'Report Pacote 07-08'!$CB:$CB,$A26,'Report Pacote 07-08'!$J:$J,$W26) -> 8647.52 | AB26: =SUMIFS('Report Pacote 07-08'!AM:AM,'Report Pacote 07-08'!$CB:$CB,$A26,'Report Pacote 07-08'!$J:$J,$W26) -> 8526.19 | AC26: =SUMIFS('Report Pacote 07-08'!AN:AN,'Report Pacote 07-08'!$CB:$CB,$A26,'Report Pacote 07-08'!$J:$J,$W26) -> 0 | AD26: =SUMIFS('Report Pacote 07-08'!AO:AO,'Report Pacote 07-08'!$CB:$CB,$A26,'Report Pacote 07-08'!$J:$J,$W26) -> 0 | AE26: =SUMIFS('Report Pacote 07-08'!AP:AP,'Report Pacote 07-08'!$CB:$CB,$A26,'Report Pacote 07-08'!$J:$J,$W26) -> 0 | AF26: =SUMIFS('Report Pacote 07-08'!AQ:AQ,'Report Pacote 07-08'!$CB:$CB,$A26,'Report Pacote 07-08'!$J:$J,$W26) -> 0 | AG26: =SUMIFS('Report Pacote 07-08'!AR:AR,'Report Pacote 07-08'!$CB:$CB,$A26,'Report Pacote 07-08'!$J:$J,$W26) -> 0 | AH26: =SUMIF($AA$7:$AG$7,"<="&$D$4,$AA26:$AG26) -> 17173.71 | AP26: =SUMIFS('Report Pacote 07-08'!AC:AC,'Report Pacote 07-08'!$CB:$CB,$A26,'Report Pacote 07-08'!$J:$J,$W26) -> 0 | AQ26: =SUMIFS('Report Pacote 07-08'!AD:AD,'Report Pacote 07-08'!$CB:$CB,$A26,'Report Pacote 07-08'!$J:$J,$W26) -> 11151.33
A29: Aterro e compactação | D29: Aterro e compactação | E29: m³ | G29: P | H29: 253268.36 | I29: =IFERROR((H30/H29),"-") -> 0.92736943 | K29: P | L29: =L33+L37+L41+L45 -> 276798.64 | M29: =IFERROR((L30/L29),"-") -> 0.91432222 | O29: P | P29: 243811.32 | Q29: =IFERROR((P30/P29),"-") -> 1.0837369 | S29: P | T29: 292078.48 | U29: 0.85425102 | W29: P | X29: =X33+X37+X41+X45 -> 48323.852 | Y29: =IFERROR((X30/X29),"-") -> 0.95484371 | AA29: =AA33+AA37+AA41+AA45 -> 48323.852 | AB29: =AB33+AB37+AB41+AB45 -> 48323.852 | AC29: =AC33+AC37+AC41+AC45 -> 48323.852 | AD29: =AD33+AD37+AD41+AD45 -> 48323.852 | AE29: =AE33+AE37+AE41+AE45 -> 45383.852 | AF29: =AF33+AF37+AF41+AF45 -> 45383.852 | AG29: =AG33+AG37+AG41+AG45 -> 0 | AH29: =SUMIF($AA$7:$AG$7,"<="&$D$4,$AA29:$AG29) -> 96647.705 | AI29: =IFERROR((AH30/AH29),"-") -> 0.94654542 | AK29: =AK33+AK37+AK41+AK45 -> 1313421.3 | AL29: =AL33+AL37+AL41+AL45 -> 576798.85 | AM29: =AM33+AM37+AM41+AM45 -> 530966.13 | AN29: =IFERROR((AM29/AL29),"-") -> 0.92053951 | AP29: =AP33+AP37+AP41+AP45 -> 2923690.2 | AQ29: =AQ33+AQ37+AQ41+AQ45 -> 2363923 | AR29: =IFERROR((AP29/AQ29),"-") -> 1.2367958 | AT29: =AT33+AT37+AT41+AT45 -> 9986485.6 | AU29: =AU33+AU37+AU41+AU45 -> 2433678 | AW29: =AW33+AW37+AW41+AW45 -> 48645.234 | AX29: =AX33+AX37+AX41+AX45 -> 44247.178 | AY29: =IF((AK29-AM29)/(Quadros!$D$4-Quadros!$D$6)<0,"-",(AK29-AM29)/(Quadros!$D$4-Quadros!$D$6)) -> 52163.679
G30: R | H30: 234873.34 | K30: R | L30: =L34+L38+L42+L46 -> 253083.15 | O30: R | P30: 264227.31 | S30: R | T30: 249508.34 | W30: R | X30: =X34+X38+X42+X46 -> 46141.727 | AA30: =AA34+AA38+AA42+AA46 -> 45339.716 | AB30: =AB34+AB38+AB42+AB46 -> 46141.727 | AC30: =AC34+AC38+AC42+AC46 -> 0 | AD30: =AD34+AD38+AD42+AD46 -> 0 | AE30: =AE34+AE38+AE42+AE46 -> 0 | AF30: =AF34+AF38+AF42+AF46 -> 0 | AG30: =AG34+AG38+AG42+AG46 -> 0 | AH30: =SUMIF($AA$7:$AG$7,"<="&$D$4,$AA30:$AG30) -> 91481.443
A33: Pacote 04 - Segmento 2.2B- Km 104+500 a Km 116+400 | D33: Pacote 04 - km 104+500 a 131+260 | E33: m³ | G33: P | H33: 4620 | I33: =IFERROR((H34/H33),"-") -> 0.8664329 | K33: P | L33: 11577 | M33: =IFERROR((L34/L33),"-") -> 0.5807584 | O33: P | P33: 12880 | Q33: =IFERROR((P34/P33),"-") -> 0.53054037 | S33: P | T33: 20539 | U33: 0.24082964 | W33: P | X33: =SUMIF($AA$7:$AG$7,"="&$D$4,$AA33:$AG33) -> 4900 | Y33: =IFERROR((X34/X33),"-") -> 0.40191837 | AA33: =SUMIFS('Report Pacote 0405'!P:P,'Report Pacote 0405'!$AV:$AV,$D$29,'Report Pacote 0405'!$AW:$AW,$A$33,'Report Pacote 0405'!$H:$H,$W33)+SUMIFS('Report Pacote 0405'!P:P,'Report Pacote 0405'!$AV:$AV,$D$29,'Report Pacote 0405'!$AW:$AW,$A$34,'Report Pacote 0405'!$H:$H,$W33) -> 4900 | AB33: =SUMIFS('Report Pacote 0405'!Q:Q,'Report Pacote 0405'!$AV:$AV,$D$29,'Report Pacote 0405'!$AW:$AW,$A$33,'Report Pacote 0405'!$H:$H,$W33)+SUMIFS('Report Pacote 0405'!Q:Q,'Report Pacote 0405'!$AV:$AV,$D$29,'Report Pacote 0405'!$AW:$AW,$A$34,'Report Pacote 0405'!$H:$H,$W33) -> 4900 | AC33: =SUMIFS('Report Pacote 0405'!R:R,'Report Pacote 0405'!$AV:$AV,$D$29,'Report Pacote 0405'!$AW:$AW,$A$33,'Report Pacote 0405'!$H:$H,$W33)+SUMIFS('Report Pacote 0405'!R:R,'Report Pacote 0405'!$AV:$AV,$D$29,'Report Pacote 0405'!$AW:$AW,$A$34,'Report Pacote 0405'!$H:$H,$W33) -> 4900 | AD33: =SUMIFS('Report Pacote 0405'!S:S,'Report Pacote 0405'!$AV:$AV,$D$29,'Report Pacote 0405'!$AW:$AW,$A$33,'Report Pacote 0405'!$H:$H,$W33)+SUMIFS('Report Pacote 0405'!S:S,'Report Pacote 0405'!$AV:$AV,$D$29,'Report Pacote 0405'!$AW:$AW,$A$34,'Report Pacote 0405'!$H:$H,$W33) -> 4900 | AE33: =SUMIFS('Report Pacote 0405'!T:T,'Report Pacote 0405'!$AV:$AV,$D$29,'Report Pacote 0405'!$AW:$AW,$A$33,'Report Pacote 0405'!$H:$H,$W33)+SUMIFS('Report Pacote 0405'!T:T,'Report Pacote 0405'!$AV:$AV,$D$29,'Report Pacote 0405'!$AW:$AW,$A$34,'Report Pacote 0405'!$H:$H,$W33) -> 4200 | AF33: =SUMIFS('Report Pacote 0405'!U:U,'Report Pacote 0405'!$AV:$AV,$D$29,'Report Pacote 0405'!$AW:$AW,$A$33,'Report Pacote 0405'!$H:$H,$W33)+SUMIFS('Report Pacote 0405'!U:U,'Report Pacote 0405'!$AV:$AV,$D$29,'Report Pacote 0405'!$AW:$AW,$A$34,'Report Pacote 0405'!$H:$H,$W33) -> 4200 | AG33: =SUMIFS('Report Pacote 0405'!V:V,'Report Pacote 0405'!$AV:$AV,$D$29,'Report Pacote 0405'!$AW:$AW,$A$33,'Report Pacote 0405'!$H:$H,$W33)+SUMIFS('Report Pacote 0405'!V:V,'Report Pacote 0405'!$AV:$AV,$D$29,'Report Pacote 0405'!$AW:$AW,$A$34,'Report Pacote 0405'!$H:$H,$W33) -> 0 | AH33: =SUMIF($AA$7:$AG$7,"<="&$D$4,$AA33:$AG33) -> 9800 | AI33: =IFERROR((AH34/AH33),"-") -> 0.24208571 | AK33: =SUMIFS('Report Pacote 0405'!AA:AA,'Report Pacote 0405'!$AV:$AV,$D$29,'Report Pacote 0405'!$AW:$AW,$A$33,'Report Pacote 0405'!$H:$H,$W33)+SUMIFS('Report Pacote 0405'!AA:AA,'Report Pacote 0405'!$AV:$AV,$D$29,'Report Pacote 0405'!$AW:$AW,$A$34,'Report Pacote 0405'!$H:$H,$W33) -> 58977.56 | AL33: =SUMIFS('Report Pacote 0405'!AB:AB,'Report Pacote 0405'!$AV:$AV,$D$29,'Report Pacote 0405'!$AW:$AW,$A$34,'Report Pacote 0405'!$H:$H,$W33)+SUMIFS('Report Pacote 0405'!AB:AB,'Report Pacote 0405'!$AV:$AV,$D$29,'Report Pacote 0405'!$AW:$AW,$A$33,'Report Pacote 0405'!$H:$H,$W33) -> 21542.52 | AM33: =SUMIFS('Report Pacote 0405'!AC:AC,'Report Pacote 0405'!$AV:$AV,$D$29,'Report Pacote 0405'!$AW:$AW,$A$33,'Report Pacote 0405'!$H:$H,$W33)+SUMIFS('Report Pacote 0405'!AC:AC,'Report Pacote 0405'!$AV:$AV,$D$29,'Report Pacote 0405'!$AW:$AW,$A$34,'Report Pacote 0405'!$H:$H,$W33) -> 12851.48 | AN33: =IFERROR((AM33/AL33),"-") -> 0.59656345 | AP33: =SUMIFS('Report Pacote 0405'!AK:AK,'Report Pacote 0405'!$AV:$AV,$D$29,'Report Pacote 0405'!$AW:$AW,$A$33,'Report Pacote 0405'!$H:$H,$W33)+SUMIFS('Report Pacote 0405'!AK:AK,'Report Pacote 0405'!$AV:$AV,$D$29,'Report Pacote 0405'!$AW:$AW,$A$34,'Report Pacote 0405'!$H:$H,$W33) -> 1715348.1 | AQ33: =SUMIFS('Report Pacote 0405'!AL:AL,'Report Pacote 0405'!$AV:$AV,$D$29,'Report Pacote 0405'!$AW:$AW,$A$33,'Report Pacote 0405'!$H:$H,$W33)+SUMIFS('Report Pacote 0405'!AL:AL,'Report Pacote 0405'!$AV:$AV,$D$29,'Report Pacote 0405'!$AW:$AW,$A$34,'Report Pacote 0405'!$H:$H,$W33) -> 1011217.9 | AR33: =IFERROR((AP33/AQ33),"-") -> 1.6963189 | AT33: =SUMIFS('Report Pacote 0405'!AO:AO,'Report Pacote 0405'!$AV:$AV,$D$29,'Report Pacote 0405'!$AW:$AW,$A$33,'Report Pacote 0405'!$H:$H,$W33)+SUMIFS('Report Pacote 0405'!AO:AO,'Report Pacote 0405'!$AV:$AV,$D$29,'Report Pacote 0405'!$AW:$AW,$A$34,'Report Pacote 0405'!$H:$H,$W33) -> 1082483.1 | AU33: =SUMIFS('Report Pacote 0405'!AP:AP,'Report Pacote 0405'!$AV:$AV,$D$29,'Report Pacote 0405'!$AW:$AW,$A$33,'Report Pacote 0405'!$H:$H,$W33)+SUMIFS('Report Pacote 0405'!AP:AP,'Report Pacote 0405'!$AV:$AV,$D$29,'Report Pacote 0405'!$AW:$AW,$A$34,'Report Pacote 0405'!$H:$H,$W33) -> -631582.56 | AW33: =AK33/Quadros!$D$4 -> 2184.3541 | AX33: =AM33/Quadros!$D$6 -> 1070.9567 | AY33: =IF((AK33-AM33)/(Quadros!$D$4-Quadros!$D$6)<0,"-",(AK33-AM33)/(Quadros!$D$4-Quadros!$D$6)) -> 3075.072
A34: Pacote 04 - Segmento 2.3 - Km 116+517 a 131+241 | G34: R | H34: 4002.92 | K34: R | L34: 6723.44 | O34: R | P34: 6833.36 | S34: R | T34: 4946.4 | W34: R | X34: =SUMIF($AA$7:$AG$7,"="&$D$4,$AA34:$AG34) -> 1969.4 | AA34: =SUMIFS('Report Pacote 0405'!P:P,'Report Pacote 0405'!$AV:$AV,$D$29,'Report Pacote 0405'!$AW:$AW,$A$33,'Report Pacote 0405'!$H:$H,$W34)+SUMIFS('Report Pacote 0405'!P:P,'Report Pacote 0405'!$AV:$AV,$D$29,'Report Pacote 0405'!$AW:$AW,$A$34,'Report Pacote 0405'!$H:$H,$W34) -> 403.04 | AB34: =SUMIFS('Report Pacote 0405'!Q:Q,'Report Pacote 0405'!$AV:$AV,$D$29,'Report Pacote 0405'!$AW:$AW,$A$33,'Report Pacote 0405'!$H:$H,$W34)+SUMIFS('Report Pacote 0405'!Q:Q,'Report Pacote 0405'!$AV:$AV,$D$29,'Report Pacote 0405'!$AW:$AW,$A$34,'Report Pacote 0405'!$H:$H,$W34) -> 1969.4 | AC34: =SUMIFS('Report Pacote 0405'!R:R,'Report Pacote 0405'!$AV:$AV,$D$29,'Report Pacote 0405'!$AW:$AW,$A$33,'Report Pacote 0405'!$H:$H,$W34)+SUMIFS('Report Pacote 0405'!R:R,'Report Pacote 0405'!$AV:$AV,$D$29,'Report Pacote 0405'!$AW:$AW,$A$34,'Report Pacote 0405'!$H:$H,$W34) -> 0 | AD34: =SUMIFS('Report Pacote 0405'!S:S,'Report Pacote 0405'!$AV:$AV,$D$29,'Report Pacote 0405'!$AW:$AW,$A$33,'Report Pacote 0405'!$H:$H,$W34)+SUMIFS('Report Pacote 0405'!S:S,'Report Pacote 0405'!$AV:$AV,$D$29,'Report Pacote 0405'!$AW:$AW,$A$34,'Report Pacote 0405'!$H:$H,$W34) -> 0 | AE34: =SUMIFS('Report Pacote 0405'!T:T,'Report Pacote 0405'!$AV:$AV,$D$29,'Report Pacote 0405'!$AW:$AW,$A$33,'Report Pacote 0405'!$H:$H,$W34)+SUMIFS('Report Pacote 0405'!T:T,'Report Pacote 0405'!$AV:$AV,$D$29,'Report Pacote 0405'!$AW:$AW,$A$34,'Report Pacote 0405'!$H:$H,$W34) -> 0 | AF34: =SUMIFS('Report Pacote 0405'!U:U,'Report Pacote 0405'!$AV:$AV,$D$29,'Report Pacote 0405'!$AW:$AW,$A$33,'Report Pacote 0405'!$H:$H,$W34)+SUMIFS('Report Pacote 0405'!U:U,'Report Pacote 0405'!$AV:$AV,$D$29,'Report Pacote 0405'!$AW:$AW,$A$34,'Report Pacote 0405'!$H:$H,$W34) -> 0 | AG34: =SUMIFS('Report Pacote 0405'!V:V,'Report Pacote 0405'!$AV:$AV,$D$29,'Report Pacote 0405'!$AW:$AW,$A$33,'Report Pacote 0405'!$H:$H,$W34)+SUMIFS('Report Pacote 0405'!V:V,'Report Pacote 0405'!$AV:$AV,$D$29,'Report Pacote 0405'!$AW:$AW,$A$34,'Report Pacote 0405'!$H:$H,$W34) -> 0 | AH34: =SUMIF($AA$7:$AG$7,"<="&$D$4,$AA34:$AG34) -> 2372.44
A37: Pacote 05 - Segmento 2.4 - Km 131+260 a Km 138+000 | D37: Pacote 05 - km 131+260 a 167+300 | E37: m³ | G37: P | H37: 84672 | I37: =IFERROR((H38/H37),"-") -> 1.1132951 | K37: P | L37: 84352 | M37: =IFERROR((L38/L37),"-") -> 1.2425597 | O37: P | P37: 90752 | Q37: =IFERROR((P38/P37),"-") -> 1.3887566 | S37: P | T37: 112496 | U37: 1.0341804 | W37: P | X37: =SUMIF($AA$7:$AG$7,"="&$D$4,$AA37:$AG37) -> 18536 | Y37: =IFERROR((X38/X37),"-") -> 1.204795 | AA37: =SUMIFS('Report Pacote 0405'!P:P,'Report Pacote 0405'!$AV:$AV,$D$29,'Report Pacote 0405'!$AW:$AW,$A$37,'Report Pacote 0405'!$H:$H,$W37)+SUMIFS('Report Pacote 0405'!P:P,'Report Pacote 0405'!$AV:$AV,$D$29,'Report Pacote 0405'!$AW:$AW,$A$38,'Report Pacote 0405'!$H:$H,$W37)+SUMIFS('Report Pacote 0405'!P:P,'Report Pacote 0405'!$AV:$AV,$D$29,'Report Pacote 0405'!$AW:$AW,$A$39,'Report Pacote 0405'!$H:$H,$W37) -> 18536 | AB37: =SUMIFS('Report Pacote 0405'!Q:Q,'Report Pacote 0405'!$AV:$AV,$D$29,'Report Pacote 0405'!$AW:$AW,$A$37,'Report Pacote 0405'!$H:$H,$W37)+SUMIFS('Report Pacote 0405'!Q:Q,'Report Pacote 0405'!$AV:$AV,$D$29,'Report Pacote 0405'!$AW:$AW,$A$38,'Report Pacote 0405'!$H:$H,$W37)+SUMIFS('Report Pacote 0405'!Q:Q,'Report Pacote 0405'!$AV:$AV,$D$29,'Report Pacote 0405'!$AW:$AW,$A$39,'Report Pacote 0405'!$H:$H,$W37) -> 18536 | AC37: =SUMIFS('Report Pacote 0405'!R:R,'Report Pacote 0405'!$AV:$AV,$D$29,'Report Pacote 0405'!$AW:$AW,$A$37,'Report Pacote 0405'!$H:$H,$W37)+SUMIFS('Report Pacote 0405'!R:R,'Report Pacote 0405'!$AV:$AV,$D$29,'Report Pacote 0405'!$AW:$AW,$A$38,'Report Pacote 0405'!$H:$H,$W37)+SUMIFS('Report Pacote 0405'!R:R,'Report Pacote 0405'!$AV:$AV,$D$29,'Report Pacote 0405'!$AW:$AW,$A$39,'Report Pacote 0405'!$H:$H,$W37) -> 18536 | AD37: =SUMIFS('Report Pacote 0405'!S:S,'Report Pacote 0405'!$AV:$AV,$D$29,'Report Pacote 0405'!$AW:$AW,$A$37,'Report Pacote 0405'!$H:$H,$W37)+SUMIFS('Report Pacote 0405'!S:S,'Report Pacote 0405'!$AV:$AV,$D$29,'Report Pacote 0405'!$AW:$AW,$A$38,'Report Pacote 0405'!$H:$H,$W37)+SUMIFS('Report Pacote 0405'!S:S,'Report Pacote 0405'!$AV:$AV,$D$29,'Report Pacote 0405'!$AW:$AW,$A$39,'Report Pacote 0405'!$H:$H,$W37) -> 18536 | AE37: =SUMIFS('Report Pacote 0405'!T:T,'Report Pacote 0405'!$AV:$AV,$D$29,'Report Pacote 0405'!$AW:$AW,$A$37,'Report Pacote 0405'!$H:$H,$W37)+SUMIFS('Report Pacote 0405'!T:T,'Report Pacote 0405'!$AV:$AV,$D$29,'Report Pacote 0405'!$AW:$AW,$A$38,'Report Pacote 0405'!$H:$H,$W37)+SUMIFS('Report Pacote 0405'!T:T,'Report Pacote 0405'!$AV:$AV,$D$29,'Report Pacote 0405'!$AW:$AW,$A$39,'Report Pacote 0405'!$H:$H,$W37) -> 16296 | AF37: =SUMIFS('Report Pacote 0405'!U:U,'Report Pacote 0405'!$AV:$AV,$D$29,'Report Pacote 0405'!$AW:$AW,$A$37,'Report Pacote 0405'!$H:$H,$W37)+SUMIFS('Report Pacote 0405'!U:U,'Report Pacote 0405'!$AV:$AV,$D$29,'Report Pacote 0405'!$AW:$AW,$A$38,'Report Pacote 0405'!$H:$H,$W37)+SUMIFS('Report Pacote 0405'!U:U,'Report Pacote 0405'!$AV:$AV,$D$29,'Report Pacote 0405'!$AW:$AW,$A$39,'Report Pacote 0405'!$H:$H,$W37) -> 16296 | AG37: =SUMIFS('Report Pacote 0405'!V:V,'Report Pacote 0405'!$AV:$AV,$D$29,'Report Pacote 0405'!$AW:$AW,$A$37,'Report Pacote 0405'!$H:$H,$W37)+SUMIFS('Report Pacote 0405'!V:V,'Report Pacote 0405'!$AV:$AV,$D$29,'Report Pacote 0405'!$AW:$AW,$A$38,'Report Pacote 0405'!$H:$H,$W37)+SUMIFS('Report Pacote 0405'!V:V,'Report Pacote 0405'!$AV:$AV,$D$29,'Report Pacote 0405'!$AW:$AW,$A$39,'Report Pacote 0405'!$H:$H,$W37) -> 0 | AH37: =SUMIF($AA$7:$AG$7,"<="&$D$4,$AA37:$AG37) -> 37072 | AI37: =IFERROR((AH38/AH37),"-") -> 1.2376575 | AK37: =SUMIFS('Report Pacote 0405'!AA:AA,'Report Pacote 0405'!$AV:$AV,$D$29,'Report Pacote 0405'!$AW:$AW,$A$38,'Report Pacote 0405'!$H:$H,$W37)+SUMIFS('Report Pacote 0405'!AA:AA,'Report Pacote 0405'!$AV:$AV,$D$29,'Report Pacote 0405'!$AW:$AW,$A$37,'Report Pacote 0405'!$H:$H,$W37)+SUMIFS('Report Pacote 0405'!AA:AA,'Report Pacote 0405'!$AV:$AV,$D$29,'Report Pacote 0405'!$AW:$AW,$A$39,'Report Pacote 0405'!$H:$H,$W37) -> 613003.13 | AL37: =SUMIFS('Report Pacote 0405'!AB:AB,'Report Pacote 0405'!$AV:$AV,$D$29,'Report Pacote 0405'!$AW:$AW,$A$38,'Report Pacote 0405'!$H:$H,$W37)+SUMIFS('Report Pacote 0405'!AB:AB,'Report Pacote 0405'!$AV:$AV,$D$29,'Report Pacote 0405'!$AW:$AW,$A$37,'Report Pacote 0405'!$H:$H,$W37)+SUMIFS('Report Pacote 0405'!AB:AB,'Report Pacote 0405'!$AV:$AV,$D$29,'Report Pacote 0405'!$AW:$AW,$A$39,'Report Pacote 0405'!$H:$H,$W37) -> 264642.37 | AM37: =SUMIFS('Report Pacote 0405'!AC:AC,'Report Pacote 0405'!$AV:$AV,$D$29,'Report Pacote 0405'!$AW:$AW,$A$38,'Report Pacote 0405'!$H:$H,$W37)+SUMIFS('Report Pacote 0405'!AC:AC,'Report Pacote 0405'!$AV:$AV,$D$29,'Report Pacote 0405'!$AW:$AW,$A$37,'Report Pacote 0405'!$H:$H,$W37)+SUMIFS('Report Pacote 0405'!AC:AC,'Report Pacote 0405'!$AV:$AV,$D$29,'Report Pacote 0405'!$AW:$AW,$A$39,'Report Pacote 0405'!$H:$H,$W37) -> 249280.24 | AN37: =IFERROR((AM37/AL37),"-") -> 0.94195136 | AP37: =SUMIFS('Report Pacote 0405'!AK:AK,'Report Pacote 0405'!$AV:$AV,$D$29,'Report Pacote 0405'!$AW:$AW,$A$38,'Report Pacote 0405'!$H:$H,$W37)+SUMIFS('Report Pacote 0405'!AK:AK,'Report Pacote 0405'!$AV:$AV,$D$29,'Report Pacote 0405'!$AW:$AW,$A$37,'Report Pacote 0405'!$H:$H,$W37)+SUMIFS('Report Pacote 0405'!AJ:AJ,'Report Pacote 0405'!$AV:$AV,$D$29,'Report Pacote 0405'!$AW:$AW,$A$39,'Report Pacote 0405'!$H:$H,$W37) -> 1144541.8 | AQ37: =SUMIFS('Report Pacote 0405'!AL:AL,'Report Pacote 0405'!$AV:$AV,$D$29,'Report Pacote 0405'!$AW:$AW,$A$38,'Report Pacote 0405'!$H:$H,$W37)+SUMIFS('Report Pacote 0405'!AL:AL,'Report Pacote 0405'!$AV:$AV,$D$29,'Report Pacote 0405'!$AW:$AW,$A$37,'Report Pacote 0405'!$H:$H,$W37)+SUMIFS('Report Pacote 0405'!AK:AK,'Report Pacote 0405'!$AV:$AV,$D$29,'Report Pacote 0405'!$AW:$AW,$A$39,'Report Pacote 0405'!$H:$H,$W37) -> 1284755.6 | AR37: =IFERROR((AP37/AQ37),"-") -> 0.89086346 | AT37: =SUMIFS('Report Pacote 0405'!AO:AO,'Report Pacote 0405'!$AV:$AV,$D$29,'Report Pacote 0405'!$AW:$AW,$A$38,'Report Pacote 0405'!$H:$H,$W37)+SUMIFS('Report Pacote 0405'!AO:AO,'Report Pacote 0405'!$AV:$AV,$D$29,'Report Pacote 0405'!$AW:$AW,$A$37,'Report Pacote 0405'!$H:$H,$W37)+SUMIFS('Report Pacote 0405'!AN:AN,'Report Pacote 0405'!$AV:$AV,$D$29,'Report Pacote 0405'!$AW:$AW,$A$39,'Report Pacote 0405'!$H:$H,$W37) -> 2263498 | AU37: =SUMIFS('Report Pacote 0405'!AP:AP,'Report Pacote 0405'!$AV:$AV,$D$29,'Report Pacote 0405'!$AW:$AW,$A$38,'Report Pacote 0405'!$H:$H,$W37)+SUMIFS('Report Pacote 0405'!AP:AP,'Report Pacote 0405'!$AV:$AV,$D$29,'Report Pacote 0405'!$AW:$AW,$A$37,'Report Pacote 0405'!$H:$H,$W37)+SUMIFS('Report Pacote 0405'!AO:AO,'Report Pacote 0405'!$AV:$AV,$D$29,'Report Pacote 0405'!$AW:$AW,$A$39,'Report Pacote 0405'!$H:$H,$W37) -> 1421654.8 | AW37: =AK37/Quadros!$D$4 -> 22703.82 | AX37: =AM37/Quadros!$D$6 -> 20773.353 | AY37: =IF((AK37-AM37)/(Quadros!$D$4-Quadros!$D$6)<0,"-",(AK37-AM37)/(Quadros!$D$4-Quadros!$D$6)) -> 24248.193
A38: Pacote 05 - Segmento 2.5 - 138+160 a 153+420 | G38: R | H38: 94264.92 | K38: R | L38: 104812.4 | O38: R | P38: 126032.44 | S38: R | T38: 116341.16 | W38: R | X38: =SUMIF($AA$7:$AG$7,"="&$D$4,$AA38:$AG38) -> 22332.08 | AA38: =SUMIFS('Report Pacote 0405'!P:P,'Report Pacote 0405'!$AV:$AV,$D$29,'Report Pacote 0405'!$AW:$AW,$A$37,'Report Pacote 0405'!$H:$H,$W38)+SUMIFS('Report Pacote 0405'!P:P,'Report Pacote 0405'!$AV:$AV,$D$29,'Report Pacote 0405'!$AW:$AW,$A$38,'Report Pacote 0405'!$H:$H,$W38)+SUMIFS('Report Pacote 0405'!P:P,'Report Pacote 0405'!$AV:$AV,$D$29,'Report Pacote 0405'!$AW:$AW,$A$39,'Report Pacote 0405'!$H:$H,$W38) -> 23550.36 | AB38: =SUMIFS('Report Pacote 0405'!Q:Q,'Report Pacote 0405'!$AV:$AV,$D$29,'Report Pacote 0405'!$AW:$AW,$A$37,'Report Pacote 0405'!$H:$H,$W38)+SUMIFS('Report Pacote 0405'!Q:Q,'Report Pacote 0405'!$AV:$AV,$D$29,'Report Pacote 0405'!$AW:$AW,$A$38,'Report Pacote 0405'!$H:$H,$W38)+SUMIFS('Report Pacote 0405'!Q:Q,'Report Pacote 0405'!$AV:$AV,$D$29,'Report Pacote 0405'!$AW:$AW,$A$39,'Report Pacote 0405'!$H:$H,$W38) -> 22332.08 | AC38: =SUMIFS('Report Pacote 0405'!R:R,'Report Pacote 0405'!$AV:$AV,$D$29,'Report Pacote 0405'!$AW:$AW,$A$37,'Report Pacote 0405'!$H:$H,$W38)+SUMIFS('Report Pacote 0405'!R:R,'Report Pacote 0405'!$AV:$AV,$D$29,'Report Pacote 0405'!$AW:$AW,$A$38,'Report Pacote 0405'!$H:$H,$W38)+SUMIFS('Report Pacote 0405'!R:R,'Report Pacote 0405'!$AV:$AV,$D$29,'Report Pacote 0405'!$AW:$AW,$A$39,'Report Pacote 0405'!$H:$H,$W38) -> 0 | AD38: =SUMIFS('Report Pacote 0405'!S:S,'Report Pacote 0405'!$AV:$AV,$D$29,'Report Pacote 0405'!$AW:$AW,$A$37,'Report Pacote 0405'!$H:$H,$W38)+SUMIFS('Report Pacote 0405'!S:S,'Report Pacote 0405'!$AV:$AV,$D$29,'Report Pacote 0405'!$AW:$AW,$A$38,'Report Pacote 0405'!$H:$H,$W38)+SUMIFS('Report Pacote 0405'!S:S,'Report Pacote 0405'!$AV:$AV,$D$29,'Report Pacote 0405'!$AW:$AW,$A$39,'Report Pacote 0405'!$H:$H,$W38) -> 0 | AE38: =SUMIFS('Report Pacote 0405'!T:T,'Report Pacote 0405'!$AV:$AV,$D$29,'Report Pacote 0405'!$AW:$AW,$A$37,'Report Pacote 0405'!$H:$H,$W38)+SUMIFS('Report Pacote 0405'!T:T,'Report Pacote 0405'!$AV:$AV,$D$29,'Report Pacote 0405'!$AW:$AW,$A$38,'Report Pacote 0405'!$H:$H,$W38)+SUMIFS('Report Pacote 0405'!T:T,'Report Pacote 0405'!$AV:$AV,$D$29,'Report Pacote 0405'!$AW:$AW,$A$39,'Report Pacote 0405'!$H:$H,$W38) -> 0 | AF38: =SUMIFS('Report Pacote 0405'!U:U,'Report Pacote 0405'!$AV:$AV,$D$29,'Report Pacote 0405'!$AW:$AW,$A$37,'Report Pacote 0405'!$H:$H,$W38)+SUMIFS('Report Pacote 0405'!U:U,'Report Pacote 0405'!$AV:$AV,$D$29,'Report Pacote 0405'!$AW:$AW,$A$38,'Report Pacote 0405'!$H:$H,$W38)+SUMIFS('Report Pacote 0405'!U:U,'Report Pacote 0405'!$AV:$AV,$D$29,'Report Pacote 0405'!$AW:$AW,$A$39,'Report Pacote 0405'!$H:$H,$W38) -> 0 | AG38: =SUMIFS('Report Pacote 0405'!V:V,'Report Pacote 0405'!$AV:$AV,$D$29,'Report Pacote 0405'!$AW:$AW,$A$37,'Report Pacote 0405'!$H:$H,$W38)+SUMIFS('Report Pacote 0405'!V:V,'Report Pacote 0405'!$AV:$AV,$D$29,'Report Pacote 0405'!$AW:$AW,$A$38,'Report Pacote 0405'!$H:$H,$W38)+SUMIFS('Report Pacote 0405'!V:V,'Report Pacote 0405'!$AV:$AV,$D$29,'Report Pacote 0405'!$AW:$AW,$A$39,'Report Pacote 0405'!$H:$H,$W38) -> 0 | AH38: =SUMIF($AA$7:$AG$7,"<="&$D$4,$AA38:$AG38) -> 45882.44
A39: Pacote 05 - Segmento 3.1 - 153+000 a 167+400
D41: Pacote 06 - km 167+300 0 a 225+000 | E41: m³ | G41: P | H41: 135586.47 | I41: =IFERROR((H42/H41),"-") -> 0.65637163 | K41: P | L41: 144455.64 | M41: =IFERROR((L42/L41),"-") -> 0.64035077 | O41: P | P41: 109394.08 | Q41: =IFERROR((P42/P41),"-") -> 0.79851343 | S41: P | T41: 123176.39 | U41: 0.71795487 | W41: P | X41: =SUMIFS('Report Pacote 06'!H:H,'Report Pacote 06'!$CH:$CH,$D$29,'Report Pacote 06'!$G:$G,'Report Consolidado Semanal'!$W41) -> 20449.398 | Y41: =IFERROR((X42/X41),"-") -> 0.76158964 | AA41: =SUMIFS('Report Pacote 06'!AG:AG,'Report Pacote 06'!$CH:$CH,$D$29,'Report Pacote 06'!$G:$G,'Report Consolidado Semanal'!$W41) -> 20449.398 | AB41: =SUMIFS('Report Pacote 06'!AH:AH,'Report Pacote 06'!$CH:$CH,$D$29,'Report Pacote 06'!$G:$G,'Report Consolidado Semanal'!$W41) -> 20449.398 | AC41: =SUMIFS('Report Pacote 06'!AI:AI,'Report Pacote 06'!$CH:$CH,$D$29,'Report Pacote 06'!$G:$G,'Report Consolidado Semanal'!$W41) -> 20449.398 | AD41: =SUMIFS('Report Pacote 06'!AJ:AJ,'Report Pacote 06'!$CH:$CH,$D$29,'Report Pacote 06'!$G:$G,'Report Consolidado Semanal'!$W41) -> 20449.398 | AE41: =SUMIFS('Report Pacote 06'!AK:AK,'Report Pacote 06'!$CH:$CH,$D$29,'Report Pacote 06'!$G:$G,'Report Consolidado Semanal'!$W41) -> 20449.398 | AF41: =SUMIFS('Report Pacote 06'!AL:AL,'Report Pacote 06'!$CH:$CH,$D$29,'Report Pacote 06'!$G:$G,'Report Consolidado Semanal'!$W41) -> 20449.398 | AG41: =SUMIFS('Report Pacote 06'!AM:AM,'Report Pacote 06'!$CH:$CH,$D$29,'Report Pacote 06'!$G:$G,'Report Consolidado Semanal'!$W41) -> 0 | AH41: =SUMIF($AA$7:$AG$7,"<="&$D$4,$AA41:$AG41) -> 40898.797 | AI41: =IFERROR((AH42/AH41),"-") -> 0.75864848 | AK41: =SUMIFS('Report Pacote 06'!BN:BN,'Report Pacote 06'!$CH:$CH,$D$29,'Report Pacote 06'!$G:$G,'Report Consolidado Semanal'!$W41) -> 483940.63 | AL41: =SUMIFS('Report Pacote 06'!BO:BO,'Report Pacote 06'!$CH:$CH,$D$29,'Report Pacote 06'!$G:$G,'Report Consolidado Semanal'!$W41) -> 215084.72 | AM41: =SUMIFS('Report Pacote 06'!BP:BP,'Report Pacote 06'!$CH:$CH,$D$29,'Report Pacote 06'!$G:$G,'Report Consolidado Semanal'!$W41) -> 172841.1 | AN41: =IFERROR((AM41/AL41),"-") -> 0.80359541 | AP41: =SUMIFS('Report Pacote 06'!BU:BU,'Report Pacote 06'!$CH:$CH,'Report Consolidado Semanal'!$D$49,'Report Pacote 06'!$G:$G,'Report Consolidado Semanal'!$W41) -> 57822.38 | AQ41: =SUMIFS('Report Pacote 06'!BX:BX,'Report Pacote 06'!$CH:$CH,'Report Consolidado Semanal'!$D$49,'Report Pacote 06'!$G:$G,'Report Consolidado Semanal'!$W41) -> 61971.608 | AR41: =IFERROR((AP41/AQ41),"-") -> 0.93304631 | AT41: =SUMIFS('Report Pacote 06'!CA:CA,'Report Pacote 06'!$CH:$CH,$D$29,'Report Pacote 06'!$G:$G,'Report Consolidado Semanal'!$W41) -> 4651600 | AU41: =SUMIFS('Report Pacote 06'!CB:CB,'Report Pacote 06'!$CH:$CH,$D$29,'Report Pacote 06'!$G:$G,'Report Consolidado Semanal'!$W41) -> 1360270.6 | AW41: =AK41/Quadros!$D$4 -> 17923.727 | AX41: =AM41/Quadros!$D$6 -> 14403.425 | AY41: =IF((AK41-AM41)/(Quadros!$D$4-Quadros!$D$6)<0,"-",(AK41-AM41)/(Quadros!$D$4-Quadros!$D$6)) -> 20739.969
G42: R | H42: 88995.11 | K42: R | L42: 92502.28 | O42: R | P42: 87352.638 | S42: R | T42: 88435.09 | W42: R | X42: =SUMIFS('Report Pacote 06'!H:H,'Report Pacote 06'!$CH:$CH,$D$29,'Report Pacote 06'!$G:$G,'Report Consolidado Semanal'!$W42) -> 15574.05 | AA42: =SUMIFS('Report Pacote 06'!AG:AG,'Report Pacote 06'!$CH:$CH,$D$29,'Report Pacote 06'!$G:$G,'Report Consolidado Semanal'!$W42) -> 15453.76 | AB42: =SUMIFS('Report Pacote 06'!AH:AH,'Report Pacote 06'!$CH:$CH,$D$29,'Report Pacote 06'!$G:$G,'Report Consolidado Semanal'!$W42) -> 15574.05 | AC42: =SUMIFS('Report Pacote 06'!AI:AI,'Report Pacote 06'!$CH:$CH,$D$29,'Report Pacote 06'!$G:$G,'Report Consolidado Semanal'!$W42) -> 0 | AD42: =SUMIFS('Report Pacote 06'!AJ:AJ,'Report Pacote 06'!$CH:$CH,$D$29,'Report Pacote 06'!$G:$G,'Report Consolidado Semanal'!$W42) -> 0 | AE42: =SUMIFS('Report Pacote 06'!AK:AK,'Report Pacote 06'!$CH:$CH,$D$29,'Report Pacote 06'!$G:$G,'Report Consolidado Semanal'!$W42) -> 0 | AF42: =SUMIFS('Report Pacote 06'!AL:AL,'Report Pacote 06'!$CH:$CH,$D$29,'Report Pacote 06'!$G:$G,'Report Consolidado Semanal'!$W42) -> 0 | AG42: =SUMIFS('Report Pacote 06'!AM:AM,'Report Pacote 06'!$CH:$CH,$D$29,'Report Pacote 06'!$G:$G,'Report Consolidado Semanal'!$W42) -> 0 | AH42: =SUMIF($AA$7:$AG$7,"<="&$D$4,$AA42:$AG42) -> 31027.81
A45: Aterro | D45: Pacote 07/08 - km 227+200 a 292+260 | E45: m³ | G45: P | H45: 28389.897 | I45: =IFERROR((H46/H45),"-") -> 1.6770186 | K45: P | L45: 36414 | M45: =IFERROR((L46/L45),"-") -> 1.3468728 | O45: P | P45: 30785.244 | Q45: =IFERROR((P46/P45),"-") -> 1.4295445 | S45: P | T45: 35867.085 | U45: 1.1092534 | W45: P | X45: =SUMIF($AA$7:$AG$7,"="&$D$4,$AA45:$AG45) -> 4438.454 | Y45: =IFERROR((X46/X45),"-") -> 1.4117971 | AA45: =SUMIFS('Report Pacote 07-08'!AL:AL,'Report Pacote 07-08'!$CB:$CB,$A45,'Report Pacote 07-08'!$J:$J,$W45) -> 4438.454 | AB45: =SUMIFS('Report Pacote 07-08'!AM:AM,'Report Pacote 07-08'!$CB:$CB,$A45,'Report Pacote 07-08'!$J:$J,$W45) -> 4438.454 | AC45: =SUMIFS('Report Pacote 07-08'!AN:AN,'Report Pacote 07-08'!$CB:$CB,$A45,'Report Pacote 07-08'!$J:$J,$W45) -> 4438.454 | AD45: =SUMIFS('Report Pacote 07-08'!AO:AO,'Report Pacote 07-08'!$CB:$CB,$A45,'Report Pacote 07-08'!$J:$J,$W45) -> 4438.454 | AE45: =SUMIFS('Report Pacote 07-08'!AP:AP,'Report Pacote 07-08'!$CB:$CB,$A45,'Report Pacote 07-08'!$J:$J,$W45) -> 4438.454 | AF45: =SUMIFS('Report Pacote 07-08'!AQ:AQ,'Report Pacote 07-08'!$CB:$CB,$A45,'Report Pacote 07-08'!$J:$J,$W45) -> 4438.454 | AG45: =SUMIFS('Report Pacote 07-08'!AR:AR,'Report Pacote 07-08'!$CB:$CB,$A45,'Report Pacote 07-08'!$J:$J,$W45) -> 0 | AH45: =SUMIF($AA$7:$AG$7,"<="&$D$4,$AA45:$AG45) -> 8876.908 | AI45: =IFERROR((AH46/AH45),"-") -> 1.3742119 | AK45: =SUMIFS('Report Pacote 07-08'!BM:BM,'Report Pacote 07-08'!$CB:$CB,$A45,'Report Pacote 07-08'!$J:$J,$W45) -> 157499.99 | AL45: =SUMIFS('Report Pacote 07-08'!BN:BN,'Report Pacote 07-08'!$CB:$CB,$A45,'Report Pacote 07-08'!$J:$J,$W45) -> 75529.237 | AM45: =SUMIFS('Report Pacote 07-08'!BO:BO,'Report Pacote 07-08'!$CB:$CB,$A45,'Report Pacote 07-08'!$J:$J,$W45) -> 95993.317 | AN45: =IFERROR((AM45/AL45),"-") -> 1.2709425 | AP45: =SUMIFS('Report Pacote 07-08'!AD:AD,'Report Pacote 07-08'!$CB:$CB,$A45,'Report Pacote 07-08'!$J:$J,$W45) -> 5977.8476 | AQ45: =SUMIFS('Report Pacote 07-08'!AI:AI,'Report Pacote 07-08'!$CB:$CB,$A45,'Report Pacote 07-08'!$J:$J,$W45) -> 5977.8476 | AR45: =IFERROR((AP45/AQ45),"-") -> 1 | AT45: =SUMIFS('Report Pacote 07-08'!BV:BV,'Report Pacote 07-08'!$CB:$CB,$A45,'Report Pacote 07-08'!$J:$J,$W45) -> 1988904.4 | AU45: =SUMIFS('Report Pacote 07-08'!BW:BW,'Report Pacote 07-08'!$CB:$CB,$A45,'Report Pacote 07-08'!$J:$J,$W45) -> 283335.16 | AW45: =AK45/Quadros!$D$4 -> 5833.3331 | AX45: =AM45/Quadros!$D$6 -> 7999.443 | AY45: =IF((AK45-AM45)/(Quadros!$D$4-Quadros!$D$6)<0,"-",(AK45-AM45)/(Quadros!$D$4-Quadros!$D$6)) -> 4100.4451
A46: Aterro | G46: R | H46: 47610.387 | K46: R | L46: 49045.027 | O46: R | P46: 44008.876 | S46: R | T46: 39785.688 | W46: R | X46: =SUMIF($AA$7:$AG$7,"="&$D$4,$AA46:$AG46) -> 6266.1965 | AA46: =SUMIFS('Report Pacote 07-08'!AL:AL,'Report Pacote 07-08'!$CB:$CB,$A46,'Report Pacote 07-08'!$J:$J,$W46) -> 5932.5563 | AB46: =SUMIFS('Report Pacote 07-08'!AM:AM,'Report Pacote 07-08'!$CB:$CB,$A46,'Report Pacote 07-08'!$J:$J,$W46) -> 6266.1965 | AC46: =SUMIFS('Report Pacote 07-08'!AN:AN,'Report Pacote 07-08'!$CB:$CB,$A46,'Report Pacote 07-08'!$J:$J,$W46) -> 0 | AD46: =SUMIFS('Report Pacote 07-08'!AO:AO,'Report Pacote 07-08'!$CB:$CB,$A46,'Report Pacote 07-08'!$J:$J,$W46) -> 0 | AE46: =SUMIFS('Report Pacote 07-08'!AP:AP,'Report Pacote 07-08'!$CB:$CB,$A46,'Report Pacote 07-08'!$J:$J,$W46) -> 0 | AF46: =SUMIFS('Report Pacote 07-08'!AQ:AQ,'Report Pacote 07-08'!$CB:$CB,$A46,'Report Pacote 07-08'!$J:$J,$W46) -> 0 | AG46: =SUMIFS('Report Pacote 07-08'!AR:AR,'Report Pacote 07-08'!$CB:$CB,$A46,'Report Pacote 07-08'!$J:$J,$W46) -> 0 | AH46: =SUMIF($AA$7:$AG$7,"<="&$D$4,$AA46:$AG46) -> 12198.753 | AP46: =SUMIFS('Report Pacote 07-08'!AC:AC,'Report Pacote 07-08'!$CB:$CB,$A46,'Report Pacote 07-08'!$J:$J,$W46) -> 0 | AQ46: =SUMIFS('Report Pacote 07-08'!AD:AD,'Report Pacote 07-08'!$CB:$CB,$A46,'Report Pacote 07-08'!$J:$J,$W46) -> 8772.1893
D49: Drenagem Superficial | E49: m | G49: P | H49: 9244.17 | I49: =IFERROR((H50/H49),"-") -> 0.70790563 | K49: P | L49: =L53+L57+L61+L65 -> 10980 | M49: =IFERROR((L50/L49),"-") -> 0.76466302 | O49: P | P49: 10525.979 | Q49: =IFERROR((P50/P49),"-") -> 0.64526065 | S49: P | T49: 11022.956 | U49: 0.820397 | W49: P | X49: =X53+X57+X61+X65 -> 1521.6726 | Y49: =IFERROR((X50/X49),"-") -> 1.1720655 | AA49: =AA53+AA57+AA61+AA65 -> 1406.6726 | AB49: =AB53+AB57+AB61+AB65 -> 1521.6726 | AC49: =AC53+AC57+AC61+AC65 -> 1632.6726 | AD49: =AD53+AD57+AD61+AD65 -> 1632.6726 | AE49: =AE53+AE57+AE61+AE65 -> 1542.6726 | AF49: =AF53+AF57+AF61+AF65 -> 1542.6726 | AG49: =AG53+AG57+AG61+AG65 -> 0 | AH49: =SUMIF($AA$7:$AG$7,"<="&$D$4,$AA49:$AG49) -> 2928.3452 | AI49: =IFERROR((AH50/AH49),"-") -> 1.1274286 | AK49: =AK53+AK57+AK61+AK65 -> 52401.283 | AL49: =AL53+AL57+AL61+AL65 -> 26120.494 | AM49: =AM53+AM57+AM61+AM65 -> 17411.2 | AN49: =IFERROR((AM49/AL49),"-") -> 0.6665724 | AP49: =AP53+AP57+AP61+AP65 -> 197382 | AQ49: =AQ53+AQ57+AQ61+AQ65 -> 215500.05 | AR49: =IFERROR((AP49/AQ49),"-") -> 0.91592553 | AT49: =AT53+AT57+AT61+AT65 -> 427960.15 | AU49: =AU53+AU57+AU61+AU65 -> 289361.64 | AW49: =AW53+AW57+AW61+AW65 -> 1940.7882 | AX49: =AX53+AX57+AX61+AX65 -> 1450.9333 | AY49: =IF((AK49-AM49)/(Quadros!$D$4-Quadros!$D$6)<0,"-",(AK49-AM49)/(Quadros!$D$4-Quadros!$D$6)) -> 2332.6722
G50: R | H50: 6544 | K50: R | L50: =L54+L58+L62+L66 -> 8396 | O50: R | P50: 6792 | S50: R | T50: 9043.2 | W50: R | X50: =X54+X58+X62+X66 -> 1783.5 | AA50: =AA54+AA58+AA62+AA66 -> 1518 | AB50: =AB54+AB58+AB62+AB66 -> 1783.5 | AC50: =AC54+AC58+AC62+AC66 -> 0 | AD50: =AD54+AD58+AD62+AD66 -> 0 | AE50: =AE54+AE58+AE62+AE66 -> 0 | AF50: =AF54+AF58+AF62+AF66 -> 0 | AG50: =AG54+AG58+AG62+AG66 -> 0 | AH50: =SUMIF($AA$7:$AG$7,"<="&$D$4,$AA50:$AG50) -> 3301.5 | BB50: saldo | BC50: necess 5
